Workbook

Sheet Start_Here
B1: Northfield Nutrition (fictional): operations workbook
B2: Portfolio demonstration with invented sample data, not client work.
B4: What this workbook does
C5: One file for the product catalog, suppliers, purchase orders, the inventory ledger, lots and expiry dates, reservations, marketing campaigns, milestones, tasks and documents. The Dashboard calculates stock, alerts and record checks from those sheets with formulas, using the as-of date on Config.
C6: Every number on the Dashboard is a formula over the other sheets. Nothing is typed into the Dashboard.
B8: Sheet guide
B9: Sheet | C9: Purpose | D9: Who types here
B10: Start_Here | C10: How the workbook works: adding records, colour key, rules, import steps, backup and recovery. | D10: Read only
B11: Dashboard | C11: Stock by SKU, reorder alerts, outstanding and overdue purchase orders, lots near expiry, open tasks, record checks, import status and a marketing summary. Formulas only. | D11: Read only
B12: Config | C12: As-of date, expiry windows, reorder and reservation rules, dropdown lists and the import check catalog. | D12: Operations lead
B13: Products | C13: Product catalog with opening balances and reorder rules. Stock columns calculate from the ledger, lots and reservations. Room for 100 rows. | D13: Operations
B14: Suppliers | C14: Supplier and manufacturing partner directory. Room for 50 rows. | D14: Operations
B15: Purchase_Orders | C15: Purchase orders and expected deliveries. Received quantities come from ledger receipts. Room for 300 rows. | D15: Purchasing
B16: Inventory_Ledger | C16: Every receipt, shipment and adjustment with lot, reference and source link. Room for 2,000 rows. | D16: Operations, import
B17: Batches | C17: Lots with company-supplied expiry dates. Lot balances, days left and expiry windows calculate. Room for 300 rows. | D17: Quality
B18: Reservations | C18: Stock set aside for orders or campaigns. Config decides which statuses count. Room for 200 rows. | D18: Sales, marketing
B19: Marketing | C19: Campaign tracker: products, channel, owner, deadlines, approval, assets, planned vs actual spend, platform-attributed revenue and company sales kept apart. Room for 100 rows. | D19: Marketing
B20: Metric_Definitions | C20: What every number means and what a blank means. | D20: Operations lead
... B26: Ready_To_Post | C26: The Ready rows of Import_Staging laid out in the column order of Inventory_Ledger, and new lots from receipts in the column order of Batches, ready to paste as values. | D26: Read only
B28: How to add a record
B29: Step 1 | C29: Go to the first empty row of the sheet. Records start on row 2.
B30: Step 2 | C30: Type only in columns with a dark blue header. A * in the header means the field is required; the header note says what goes in it.
B31: Step 3 | C31: Use the dropdowns for statuses and for SKU, supplier and lot IDs. IDs must be unique: a repeated ID is refused or flagged.
B32: Step 4 | C32: Grey-header columns calculate by themselves and are locked. Do not insert rows or columns: each sheet already has formulas in its spare rows (room listed in the sheet guide).
B33: Step 5 | C33: Read the Record check column at the right of the row. It says OK, or names the first problem in the row. The Dashboard counts every row that is not OK.
B35: Colour key
B36: Dark blue header | C36: You type in this column.
B37: Grey header | C37: Calculated column, locked.
B38: Light grey header | C38: Helper column used by the Dashboard or Exceptions lists, locked.
B39: Amber | C39: Attention: below reorder point, lot in the second expiry window, or overdue document review.
B40: Orange | C40: Lot in the first expiry window.
B41: Light yellow | C41: Lot in the third expiry window.
B42: Red | C42: Problem: overdue PO or task, expired lot with stock, negative stock, record check not OK, rejected import row.
B43: Green | C43: Import row ready to post.
B45: Rules (change them on Config)
B46: Recorded stock | C46: Opening balance + receipts - shipments + adjustments, per SKU, from Inventory_Ledger.
B47: Lot balances | C47: Lot opening qty + ledger movements for that lot. The lot balances of a SKU must add up to its recorded stock; Products flags any gap.
B48: Available stock | C48: Recorded stock - reserved - held in lots. Reservations count when their status holds stock on Config, the start date is on or before the as-of date, and the release date is empty or on or after it. Lots count as held when their status holds stock on Config, or when they are expired and Config says expired lots are held.
B49: Reorder alert | C49: The stock chosen on Config (Available or Recorded) is below the SKU's reorder point.
B50: Purchase orders | C50: Open = status counts as open on Config and the ordered qty is not fully received in the ledger. Overdue = open and the expected date is before the as-of date.
...

Sheet Dashboard
B1: Northfield Nutrition (fictional): operations dashboard | S1: =Config!$B$6 -> 30
B2: Portfolio demonstration with invented sample data, not client work. | S2: =Config!$B$7 -> 60
B3: ="As of "&TEXT(Config!$B$4,"yyyy-mm-dd")&" · every figure is a formula over the record sheets · change the date or the rules on Config" -> As of 2026-10-15 · every figure is a formula over the record sheets · change the date or the rules on Config | S3: =Config!$B$8 -> 90
B5: Stock and purchasing | D5: SKUs tracked | F5: Recorded units | H5: Available units | J5: SKUs below reorder | L5: Open POs | N5: Overdue POs | P5: Open tasks
B6: Each tile is a formula; see Metric_Definitions. | D6: =SUMPRODUCT(--(Products!$A$2:$A$101<>"")) -> 12 | F6: =SUM(Products!$R$2:$R$101) -> 9234 | H6: =SUM(Products!$U$2:$U$101) -> 8048 | J6: =SUM(Products!$Y$2:$Y$101) -> 4 | L6: =SUM(Purchase_Orders!$O$2:$O$301) -> 5 | N6: =SUM(Purchase_Orders!$P$2:$P$301) -> 2 | P6: =SUM(Tasks!$I$2:$I$301) -> 9
D7: ="rows in Products" -> rows in Products | F7: ="opening + receipts - shipments + adjustments" -> opening + receipts - shipments + adjustments | H7: ="recorded - reserved - held in lots" -> recorded - reserved - held in lots | J7: ="test uses "&LOWER(Config!$B$9)&" stock" -> test uses available stock | L7: =TEXT(SUMIFS(Purchase_Orders!$N$2:$N$301,Purchase_Orders!$O$2:$O$301,1),"#,##0")&" units on order" -> 3,560 units on order | N7: ="expected date has passed" -> expected date has passed | P7: =SUM(Tasks!$J$2:$J$301)&" overdue" -> 2 overdue
B9: Expiry, imports and checks | D9: Expired lots with stock | F9: ="Lots expiring in "&0&"-"&Config!$B$6&" days" -> Lots expiring in 0-30 days | H9: ="Lots expiring in "&(Config!$B$6+1)&"-"&Config!$B$7&" days" -> Lots expiring in 31-60 days | J9: ="Lots expiring in "&(Config!$B$7+1)&"-"&Config!$B$8&" days" -> Lots expiring in 61-90 days | L9: Import rows ready | N9: Import exceptions | P9: Record issues
B10: Each tile is a formula; see Metric_Definitions. | D10: =COUNTIFS(Batches!$L$2:$L$301,">0",Batches!$M$2:$M$301,"<0") -> 1 | F10: =COUNTIFS(Batches!$L$2:$L$301,">0",Batches!$M$2:$M$301,">=0",Batches!$M$2:$M$301,"<="&Config!$B$6) -> 3 | H10: =COUNTIFS(Batches!$L$2:$L$301,">0",Batches!$M$2:$M$301,">"&Config!$B$6,Batches!$M$2:$M$301,"<="&Config!$B$7) -> 2 | J10: =COUNTIFS(Batches!$L$2:$L$301,">0",Batches!$M$2:$M$301,">"&Config!$B$7,Batches!$M$2:$M$301,"<="&Config!$B$8) -> 3 | L10: =COUNTIF(Import_Staging!$U$2:$U$301,"Ready") -> 8 | N10: =SUM(Import_Staging!$T$2:$T$301) -> 11 | P10: =$E$107 -> 0
D11: ="expiry date has passed" -> expiry date has passed | F11: ="lots with stock on hand" -> lots with stock on hand | H11: ="lots with stock on hand" -> lots with stock on hand | J11: ="lots with stock on hand" -> lots with stock on hand | L11: ="of "&(COUNTIF(Import_Staging!$U$2:$U$301,"Ready")+COUNTIF(Import_Staging!$U$2:$U$301,"Rejected"))&" rows staged" -> of 18 rows staged | N11: =COUNTIF(Import_Staging!$U$2:$U$301,"Rejected")&" rows rejected" -> 10 rows rejected | P11: ="missing or inconsistent rows" -> missing or inconsistent rows
B13: Reorder alerts
B14: ="SKUs whose "&LOWER(Config!$B$9)&" stock is below the reorder point. Up to 15 shown; the tile counts all." -> SKUs whose available stock is below the reorder point. Up to 15 shown; the tile counts all.
B15: SKU | C15: Product | D15: Recorded | E15: Reserved | F15: Held in lots | G15: Available | H15: Reorder point | I15: Reorder qty | J15: On order | K15: Status | L15: Supplier
A16: =IFERROR(MATCH(1,Products!$AC$2:$AC$101,0),"") -> 1 | B16: =IF($A16="","",INDEX(Products!$A$2:$A$101,$A16)&"") -> WPI-CHO-2LB | C16: =IF($A16="","",INDEX(Products!$B$2:$B$101,$A16)&"") -> Whey Protein Isolate, Chocolate, 2 lb | D16: =IF($A16="","",INDEX(Products!$R$2:$R$101,$A16)) -> 429 | E16: =IF($A16="","",INDEX(Products!$S$2:$S$101,$A16)) -> 120 | F16: =IF($A16="","",INDEX(Products!$T$2:$T$101,$A16)) -> 0 | G16: =IF($A16="","",INDEX(Products!$U$2:$U$101,$A16)) -> 309 | H16: =IF($A16="","",INDEX(Products!$I$2:$I$101,$A16)) -> 600 | I16: =IF($A16="","",INDEX(Products!$J$2:$J$101,$A16)) -> 1500 | J16: =IF($A16="","",INDEX(Products!$V$2:$V$101,$A16)) -> 1500 | K16: =IF($A16="","",INDEX(Products!$Z$2:$Z$101,$A16)&"") -> Below reorder | L16: =IF($A16="","",INDEX(Products!$N$2:$N$101,$A16)&"") -> Alder Creek Dairy Proteins
A17: =IFERROR(MATCH(2,Products!$AC$2:$AC$101,0),"") -> 2 | B17: =IF($A17="","",INDEX(Products!$A$2:$A$101,$A17)&"") -> WPI-VAN-2LB | C17: =IF($A17="","",INDEX(Products!$B$2:$B$101,$A17)&"") -> Whey Protein Isolate, Vanilla, 2 lb | D17: =IF($A17="","",INDEX(Products!$R$2:$R$101,$A17)) -> 808 | E17: =IF($A17="","",INDEX(Products!$S$2:$S$101,$A17)) -> 0 | F17: =IF($A17="","",INDEX(Products!$T$2:$T$101,$A17)) -> 600 | G17: =IF($A17="","",INDEX(Products!$U$2:$U$101,$A17)) -> 208 | H17: =IF($A17="","",INDEX(Products!$I$2:$I$101,$A17)) -> 450 | I17: =IF($A17="","",INDEX(Products!$J$2:$J$101,$A17)) -> 1200 | J17: =IF($A17="","",INDEX(Products!$V$2:$V$101,$A17)) -> 600 | K17: =IF($A17="","",INDEX(Products!$Z$2:$Z$101,$A17)&"") -> Below reorder | L17: =IF($A17="","",INDEX(Products!$N$2:$N$101,$A17)&"") -> Alder Creek Dairy Proteins
A18: =IFERROR(MATCH(3,Products!$AC$2:$AC$101,0),"") -> 5 | B18: =IF($A18="","",INDEX(Products!$A$2:$A$101,$A18)&"") -> PLT-VAN-2LB | C18: =IF($A18="","",INDEX(Products!$B$2:$B$101,$A18)&"") -> Plant Protein, Vanilla, 2 lb | D18: =IF($A18="","",INDEX(Products!$R$2:$R$101,$A18)) -> 133 | E18: =IF($A18="","",INDEX(Products!$S$2:$S$101,$A18)) -> 0 | F18: =IF($A18="","",INDEX(Products!$T$2:$T$101,$A18)) -> 0 | G18: =IF($A18="","",INDEX(Products!$U$2:$U$101,$A18)) -> 133 | H18: =IF($A18="","",INDEX(Products!$I$2:$I$101,$A18)) -> 200 | I18: =IF($A18="","",INDEX(Products!$J$2:$J$101,$A18)) -> 500 | J18: =IF($A18="","",INDEX(Products!$V$2:$V$101,$A18)) -> 500 | K18: =IF($A18="","",INDEX(Products!$Z$2:$Z$101,$A18)&"") -> Below reorder | L18: =IF($A18="","",INDEX(Products!$N$2:$N$101,$A18)&"") -> Corliss Plant Proteins
A19: =IFERROR(MATCH(4,Products!$AC$2:$AC$101,0),"") -> 9 | B19: =IF($A19="","",INDEX(Products!$A$2:$A$101,$A19)&"") -> CRE-UNF-500G | C19: =IF($A19="","",INDEX(Products!$B$2:$B$101,$A19)&"") -> Creatine Monohydrate, Unflavoured, 500 g | D19: =IF($A19="","",INDEX(Products!$R$2:$R$101,$A19)) -> 290 | E19: =IF($A19="","",INDEX(Products!$S$2:$S$101,$A19)) -> 80 | F19: =IF($A19="","",INDEX(Products!$T$2:$T$101,$A19)) -> 0 | G19: =IF($A19="","",INDEX(Products!$U$2:$U$101,$A19)) -> 210 | H19: =IF($A19="","",INDEX(Products!$I$2:$I$101,$A19)) -> 250 | I19: =IF($A19="","",INDEX(Products!$J$2:$J$101,$A19)) -> 700 | J19: =IF($A19="","",INDEX(Products!$V$2:$V$101,$A19)) -> 0 | K19: =IF($A19="","",INDEX(Products!$Z$2:$Z$101,$A19)&"") -> Below reorder | L19: =IF($A19="","",INDEX(Products!$N$2:$N$101,$A19)&"") -> Dunmore Powder Labs
A20: =IFERROR(MATCH(5,Products!$AC$2:$AC$101,0),"") | B20: =IF($A20="","",INDEX(Products!$A$2:$A$101,$A20)&"") | C20: =IF($A20="","",INDEX(Products!$B$2:$B$101,$A20)&"") | D20: =IF($A20="","",INDEX(Products!$R$2:$R$101,$A20)) | E20: =IF($A20="","",INDEX(Products!$S$2:$S$101,$A20)) | F20: =IF($A20="","",INDEX(Products!$T$2:$T$101,$A20)) | G20: =IF($A20="","",INDEX(Products!$U$2:$U$101,$A20)) | H20: =IF($A20="","",INDEX(Products!$I$2:$I$101,$A20)) | I20: =IF($A20="","",INDEX(Products!$J$2:$J$101,$A20)) | J20: =IF($A20="","",INDEX(Products!$V$2:$V$101,$A20)) | K20: =IF($A20="","",INDEX(Products!$Z$2:$Z$101,$A20)&"") | L20: =IF($A20="","",INDEX(Products!$N$2:$N$101,$A20)&"")
A21: =IFERROR(MATCH(6,Products!$AC$2:$AC$101,0),"") | B21: =IF($A21="","",INDEX(Products!$A$2:$A$101,$A21)&"") | C21: =IF($A21="","",INDEX(Products!$B$2:$B$101,$A21)&"") | D21: =IF($A21="","",INDEX(Products!$R$2:$R$101,$A21)) | E21: =IF($A21="","",INDEX(Products!$S$2:$S$101,$A21)) | F21: =IF($A21="","",INDEX(Products!$T$2:$T$101,$A21)) | G21: =IF($A21="","",INDEX(Products!$U$2:$U$101,$A21)) | H21: =IF($A21="","",INDEX(Products!$I$2:$I$101,$A21)) | I21: =IF($A21="","",INDEX(Products!$J$2:$J$101,$A21)) | J21: =IF($A21="","",INDEX(Products!$V$2:$V$101,$A21)) | K21: =IF($A21="","",INDEX(Products!$Z$2:$Z$101,$A21)&"") | L21: =IF($A21="","",INDEX(Products!$N$2:$N$101,$A21)&"")
A22: =IFERROR(MATCH(7,Products!$AC$2:$AC$101,0),"") | B22: =IF($A22="","",INDEX(Products!$A$2:$A$101,$A22)&"") | C22: =IF($A22="","",INDEX(Products!$B$2:$B$101,$A22)&"") | D22: =IF($A22="","",INDEX(Products!$R$2:$R$101,$A22)) | E22: =IF($A22="","",INDEX(Products!$S$2:$S$101,$A22)) | F22: =IF($A22="","",INDEX(Products!$T$2:$T$101,$A22)) | G22: =IF($A22="","",INDEX(Products!$U$2:$U$101,$A22)) | H22: =IF($A22="","",INDEX(Products!$I$2:$I$101,$A22)) | I22: =IF($A22="","",INDEX(Products!$J$2:$J$101,$A22)) | J22: =IF($A22="","",INDEX(Products!$V$2:$V$101,$A22)) | K22: =IF($A22="","",INDEX(Products!$Z$2:$Z$101,$A22)&"") | L22: =IF($A22="","",INDEX(Products!$N$2:$N$101,$A22)&"")
A23: =IFERROR(MATCH(8,Products!$AC$2:$AC$101,0),"") | B23: =IF($A23="","",INDEX(Products!$A$2:$A$101,$A23)&"") | C23: =IF($A23="","",INDEX(Products!$B$2:$B$101,$A23)&"") | D23: =IF($A23="","",INDEX(Products!$R$2:$R$101,$A23)) | E23: =IF($A23="","",INDEX(Products!$S$2:$S$101,$A23)) | F23: =IF($A23="","",INDEX(Products!$T$2:$T$101,$A23)) | G23: =IF($A23="","",INDEX(Products!$U$2:$U$101,$A23)) | H23: =IF($A23="","",INDEX(Products!$I$2:$I$101,$A23)) | I23: =IF($A23="","",INDEX(Products!$J$2:$J$101,$A23)) | J23: =IF($A23="","",INDEX(Products!$V$2:$V$101,$A23)) | K23: =IF($A23="","",INDEX(Products!$Z$2:$Z$101,$A23)&"") | L23: =IF($A23="","",INDEX(Products!$N$2:$N$101,$A23)&"")
A24: =IFERROR(MATCH(9,Products!$AC$2:$AC$101,0),"") | B24: =IF($A24="","",INDEX(Products!$A$2:$A$101,$A24)&"") | C24: =IF($A24="","",INDEX(Products!$B$2:$B$101,$A24)&"") | D24: =IF($A24="","",INDEX(Products!$R$2:$R$101,$A24)) | E24: =IF($A24="","",INDEX(Products!$S$2:$S$101,$A24)) | F24: =IF($A24="","",INDEX(Products!$T$2:$T$101,$A24)) | G24: =IF($A24="","",INDEX(Products!$U$2:$U$101,$A24)) | H24: =IF($A24="","",INDEX(Products!$I$2:$I$101,$A24)) | I24: =IF($A24="","",INDEX(Products!$J$2:$J$101,$A24)) | J24: =IF($A24="","",INDEX(Products!$V$2:$V$101,$A24)) | K24: =IF($A24="","",INDEX(Products!$Z$2:$Z$101,$A24)&"") | L24: =IF($A24="","",INDEX(Products!$N$2:$N$101,$A24)&"")
A25: =IFERROR(MATCH(10,Products!$AC$2:$AC$101,0),"") | B25: =IF($A25="","",INDEX(Products!$A$2:$A$101,$A25)&"") | C25: =IF($A25="","",INDEX(Products!$B$2:$B$101,$A25)&"") | D25: =IF($A25="","",INDEX(Products!$R$2:$R$101,$A25)) | E25: =IF($A25="","",INDEX(Products!$S$2:$S$101,$A25)) | F25: =IF($A25="","",INDEX(Products!$T$2:$T$101,$A25)) | G25: =IF($A25="","",INDEX(Products!$U$2:$U$101,$A25)) | H25: =IF($A25="","",INDEX(Products!$I$2:$I$101,$A25)) | I25: =IF($A25="","",INDEX(Products!$J$2:$J$101,$A25)) | J25: =IF($A25="","",INDEX(Products!$V$2:$V$101,$A25)) | K25: =IF($A25="","",INDEX(Products!$Z$2:$Z$101,$A25)&"") | L25: =IF($A25="","",INDEX(Products!$N$2:$N$101,$A25)&"")
A26: =IFERROR(MATCH(11,Products!$AC$2:$AC$101,0),"") | B26: =IF($A26="","",INDEX(Products!$A$2:$A$101,$A26)&"") | C26: =IF($A26="","",INDEX(Products!$B$2:$B$101,$A26)&"") | D26: =IF($A26="","",INDEX(Products!$R$2:$R$101,$A26)) | E26: =IF($A26="","",INDEX(Products!$S$2:$S$101,$A26)) | F26: =IF($A26="","",INDEX(Products!$T$2:$T$101,$A26)) | G26: =IF($A26="","",INDEX(Products!$U$2:$U$101,$A26)) | H26: =IF($A26="","",INDEX(Products!$I$2:$I$101,$A26)) | I26: =IF($A26="","",INDEX(Products!$J$2:$J$101,$A26)) | J26: =IF($A26="","",INDEX(Products!$V$2:$V$101,$A26)) | K26: =IF($A26="","",INDEX(Products!$Z$2:$Z$101,$A26)&"") | L26: =IF($A26="","",INDEX(Products!$N$2:$N$101,$A26)&"")
A27: =IFERROR(MATCH(12,Products!$AC$2:$AC$101,0),"") | B27: =IF($A27="","",INDEX(Products!$A$2:$A$101,$A27)&"") | C27: =IF($A27="","",INDEX(Products!$B$2:$B$101,$A27)&"") | D27: =IF($A27="","",INDEX(Products!$R$2:$R$101,$A27)) | E27: =IF($A27="","",INDEX(Products!$S$2:$S$101,$A27)) | F27: =IF($A27="","",INDEX(Products!$T$2:$T$101,$A27)) | G27: =IF($A27="","",INDEX(Products!$U$2:$U$101,$A27)) | H27: =IF($A27="","",INDEX(Products!$I$2:$I$101,$A27)) | I27: =IF($A27="","",INDEX(Products!$J$2:$J$101,$A27)) | J27: =IF($A27="","",INDEX(Products!$V$2:$V$101,$A27)) | K27: =IF($A27="","",INDEX(Products!$Z$2:$Z$101,$A27)&"") | L27: =IF($A27="","",INDEX(Products!$N$2:$N$101,$A27)&"")
A28: =IFERROR(MATCH(13,Products!$AC$2:$AC$101,0),"") | B28: =IF($A28="","",INDEX(Products!$A$2:$A$101,$A28)&"") | C28: =IF($A28="","",INDEX(Products!$B$2:$B$101,$A28)&"") | D28: =IF($A28="","",INDEX(Products!$R$2:$R$101,$A28)) | E28: =IF($A28="","",INDEX(Products!$S$2:$S$101,$A28)) | F28: =IF($A28="","",INDEX(Products!$T$2:$T$101,$A28)) | G28: =IF($A28="","",INDEX(Products!$U$2:$U$101,$A28)) | H28: =IF($A28="","",INDEX(Products!$I$2:$I$101,$A28)) | I28: =IF($A28="","",INDEX(Products!$J$2:$J$101,$A28)) | J28: =IF($A28="","",INDEX(Products!$V$2:$V$101,$A28)) | K28: =IF($A28="","",INDEX(Products!$Z$2:$Z$101,$A28)&"") | L28: =IF($A28="","",INDEX(Products!$N$2:$N$101,$A28)&"")
A29: =IFERROR(MATCH(14,Products!$AC$2:$AC$101,0),"") | B29: =IF($A29="","",INDEX(Products!$A$2:$A$101,$A29)&"") | C29: =IF($A29="","",INDEX(Products!$B$2:$B$101,$A29)&"") | D29: =IF($A29="","",INDEX(Products!$R$2:$R$101,$A29)) | E29: =IF($A29="","",INDEX(Products!$S$2:$S$101,$A29)) | F29: =IF($A29="","",INDEX(Products!$T$2:$T$101,$A29)) | G29: =IF($A29="","",INDEX(Products!$U$2:$U$101,$A29)) | H29: =IF($A29="","",INDEX(Products!$I$2:$I$101,$A29)) | I29: =IF($A29="","",INDEX(Products!$J$2:$J$101,$A29)) | J29: =IF($A29="","",INDEX(Products!$V$2:$V$101,$A29)) | K29: =IF($A29="","",INDEX(Products!$Z$2:$Z$101,$A29)&"") | L29: =IF($A29="","",INDEX(Products!$N$2:$N$101,$A29)&"")
A30: =IFERROR(MATCH(15,Products!$AC$2:$AC$101,0),"") | B30: =IF($A30="","",INDEX(Products!$A$2:$A$101,$A30)&"") | C30: =IF($A30="","",INDEX(Products!$B$2:$B$101,$A30)&"") | D30: =IF($A30="","",INDEX(Products!$R$2:$R$101,$A30)) | E30: =IF($A30="","",INDEX(Products!$S$2:$S$101,$A30)) | F30: =IF($A30="","",INDEX(Products!$T$2:$T$101,$A30)) | G30: =IF($A30="","",INDEX(Products!$U$2:$U$101,$A30)) | H30: =IF($A30="","",INDEX(Products!$I$2:$I$101,$A30)) | I30: =IF($A30="","",INDEX(Products!$J$2:$J$101,$A30)) | J30: =IF($A30="","",INDEX(Products!$V$2:$V$101,$A30)) | K30: =IF($A30="","",INDEX(Products!$Z$2:$Z$101,$A30)&"") | L30: =IF($A30="","",INDEX(Products!$N$2:$N$101,$A30)&"")
B32: Outstanding purchase orders
B33: Open POs, earliest expected date first. Up to 15 shown.
B34: PO | C34: Supplier | D34: SKU | E34: Ordered | F34: Received | G34: Outstanding | H34: Order date | I34: Expected | J34: Status | K34: Overdue | L34: Days late
A35: =IFERROR(MATCH(1,Purchase_Orders!$T$2:$T$301,0),"") -> 8 | B35: =IF($A35="","",INDEX(Purchase_Orders!$A$2:$A$301,$A35)&"") -> PO-2026-029 | C35: =IF($A35="","",INDEX(Purchase_Orders!$K$2:$K$301,$A35)&"") -> Corliss Plant Proteins | D35: =IF($A35="","",INDEX(Purchase_Orders!$C$2:$C$301,$A35)&"") -> PLT-VAN-2LB | E35: =IF($A35="","",INDEX(Purchase_Orders!$D$2:$D$301,$A35)) -> 500 | F35: =IF($A35="","",INDEX(Purchase_Orders!$M$2:$M$301,$A35)) -> 0 | G35: =IF($A35="","",INDEX(Purchase_Orders!$N$2:$N$301,$A35)) -> 500 | H35: =IF($A35="","",INDEX(Purchase_Orders!$F$2:$F$301,$A35)) -> 46266 | I35: =IF($A35="","",INDEX(Purchase_Orders!$G$2:$G$301,$A35)) -> 46301 | J35: =IF($A35="","",INDEX(Purchase_Orders!$H$2:$H$301,$A35)&"") -> Confirmed | K35: =IF($A35="","",IF(INDEX(Purchase_Orders!$P$2:$P$301,$A35)=1,"Yes","")) -> Yes | L35: =IF($A35="","",INDEX(Purchase_Orders!$Q$2:$Q$301,$A35)) -> 9
A36: =IFERROR(MATCH(2,Purchase_Orders!$T$2:$T$301,0),"") -> 10 | B36: =IF($A36="","",INDEX(Purchase_Orders!$A$2:$A$301,$A36)&"") -> PO-2026-031 | C36: =IF($A36="","",INDEX(Purchase_Orders!$K$2:$K$301,$A36)&"") -> Dunmore Powder Labs | D36: =IF($A36="","",INDEX(Purchase_Orders!$C$2:$C$301,$A36)&"") -> PRE-WTM-30 | E36: =IF($A36="","",INDEX(Purchase_Orders!$D$2:$D$301,$A36)) -> 600 | F36: =IF($A36="","",INDEX(Purchase_Orders!$M$2:$M$301,$A36)) -> 0 | G36: =IF($A36="","",INDEX(Purchase_Orders!$N$2:$N$301,$A36)) -> 600 | H36: =IF($A36="","",INDEX(Purchase_Orders!$F$2:$F$301,$A36)) -> 46269 | I36: =IF($A36="","",INDEX(Purchase_Orders!$G$2:$G$301,$A36)) -> 46305 | J36: =IF($A36="","",INDEX(Purchase_Orders!$H$2:$H$301,$A36)&"") -> In transit | K36: =IF($A36="","",IF(INDEX(Purchase_Orders!$P$2:$P$301,$A36)=1,"Yes","")) -> Yes | L36: =IF($A36="","",INDEX(Purchase_Orders!$Q$2:$Q$301,$A36)) -> 5
A37: =IFERROR(MATCH(3,Purchase_Orders!$T$2:$T$301,0),"") -> 9 | B37: =IF($A37="","",INDEX(Purchase_Orders!$A$2:$A$301,$A37)&"") -> PO-2026-030 | C37: =IF($A37="","",INDEX(Purchase_Orders!$K$2:$K$301,$A37)&"") -> Alder Creek Dairy Proteins | D37: =IF($A37="","",INDEX(Purchase_Orders!$C$2:$C$301,$A37)&"") -> WPI-CHO-2LB | E37: =IF($A37="","",INDEX(Purchase_Orders!$D$2:$D$301,$A37)) -> 1500 | F37: =IF($A37="","",INDEX(Purchase_Orders!$M$2:$M$301,$A37)) -> 0 | G37: =IF($A37="","",INDEX(Purchase_Orders!$N$2:$N$301,$A37)) -> 1500 | H37: =IF($A37="","",INDEX(Purchase_Orders!$F$2:$F$301,$A37)) -> 46280 | I37: =IF($A37="","",INDEX(Purchase_Orders!$G$2:$G$301,$A37)) -> 46315 | J37: =IF($A37="","",INDEX(Purchase_Orders!$H$2:$H$301,$A37)&"") -> In transit | K37: =IF($A37="","",IF(INDEX(Purchase_Orders!$P$2:$P$301,$A37)=1,"Yes","")) | L37: =IF($A37="","",INDEX(Purchase_Orders!$Q$2:$Q$301,$A37)) -> 0
A38: =IFERROR(MATCH(4,Purchase_Orders!$T$2:$T$301,0),"") -> 6 | B38: =IF($A38="","",INDEX(Purchase_Orders!$A$2:$A$301,$A38)&"") -> PO-2026-027 | C38: =IF($A38="","",INDEX(Purchase_Orders!$K$2:$K$301,$A38)&"") -> Alder Creek Dairy Proteins | D38: =IF($A38="","",INDEX(Purchase_Orders!$C$2:$C$301,$A38)&"") -> WPI-VAN-2LB | E38: =IF($A38="","",INDEX(Purchase_Orders!$D$2:$D$301,$A38)) -> 1200 | F38: =IF($A38="","",INDEX(Purchase_Orders!$M$2:$M$301,$A38)) -> 600 | G38: =IF($A38="","",INDEX(Purchase_Orders!$N$2:$N$301,$A38)) -> 600 | H38: =IF($A38="","",INDEX(Purchase_Orders!$F$2:$F$301,$A38)) -> 46267 | I38: =IF($A38="","",INDEX(Purchase_Orders!$G$2:$G$301,$A38)) -> 46324 | J38: =IF($A38="","",INDEX(Purchase_Orders!$H$2:$H$301,$A38)&"") -> Partially received | K38: =IF($A38="","",IF(INDEX(Purchase_Orders!$P$2:$P$301,$A38)=1,"Yes","")) | L38: =IF($A38="","",INDEX(Purchase_Orders!$Q$2:$Q$301,$A38)) -> 0
A39: =IFERROR(MATCH(5,Purchase_Orders!$T$2:$T$301,0),"") -> 11 | B39: =IF($A39="","",INDEX(Purchase_Orders!$A$2:$A$301,$A39)&"") -> PO-2026-032 | C39: =IF($A39="","",INDEX(Purchase_Orders!$K$2:$K$301,$A39)&"") -> Elmstead Co-Packing | D39: =IF($A39="","",INDEX(Purchase_Orders!$C$2:$C$301,$A39)&"") -> CAS-CHO-2LB | E39: =IF($A39="","",INDEX(Purchase_Orders!$D$2:$D$301,$A39)) -> 360 | F39: =IF($A39="","",INDEX(Purchase_Orders!$M$2:$M$301,$A39)) -> 0 | G39: =IF($A39="","",INDEX(Purchase_Orders!$N$2:$N$301,$A39)) -> 360 | H39: =IF($A39="","",INDEX(Purchase_Orders!$F$2:$F$301,$A39)) -> 46300 | I39: =IF($A39="","",INDEX(Purchase_Orders!$G$2:$G$301,$A39)) -> 46345 | J39: =IF($A39="","",INDEX(Purchase_Orders!$H$2:$H$301,$A39)&"") -> Ordered | K39: =IF($A39="","",IF(INDEX(Purchase_Orders!$P$2:$P$301,$A39)=1,"Yes","")) | L39: =IF($A39="","",INDEX(Purchase_Orders!$Q$2:$Q$301,$A39)) -> 0
A40: =IFERROR(MATCH(6,Purchase_Orders!$T$2:$T$301,0),"") | B40: =IF($A40="","",INDEX(Purchase_Orders!$A$2:$A$301,$A40)&"") | C40: =IF($A40="","",INDEX(Purchase_Orders!$K$2:$K$301,$A40)&"") | D40: =IF($A40="","",INDEX(Purchase_Orders!$C$2:$C$301,$A40)&"") | E40: =IF($A40="","",INDEX(Purchase_Orders!$D$2:$D$301,$A40)) | F40: =IF($A40="","",INDEX(Purchase_Orders!$M$2:$M$301,$A40)) | G40: =IF($A40="","",INDEX(Purchase_Orders!$N$2:$N$301,$A40)) | H40: =IF($A40="","",INDEX(Purchase_Orders!$F$2:$F$301,$A40)) | I40: =IF($A40="","",INDEX(Purchase_Orders!$G$2:$G$301,$A40)) | J40: =IF($A40="","",INDEX(Purchase_Orders!$H$2:$H$301,$A40)&"") | K40: =IF($A40="","",IF(INDEX(Purchase_Orders!$P$2:$P$301,$A40)=1,"Yes","")) | L40: =IF($A40="","",INDEX(Purchase_Orders!$Q$2:$Q$301,$A40))
A41: =IFERROR(MATCH(7,Purchase_Orders!$T$2:$T$301,0),"") | B41: =IF($A41="","",INDEX(Purchase_Orders!$A$2:$A$301,$A41)&"") | C41: =IF($A41="","",INDEX(Purchase_Orders!$K$2:$K$301,$A41)&"") | D41: =IF($A41="","",INDEX(Purchase_Orders!$C$2:$C$301,$A41)&"") | E41: =IF($A41="","",INDEX(Purchase_Orders!$D$2:$D$301,$A41)) | F41: =IF($A41="","",INDEX(Purchase_Orders!$M$2:$M$301,$A41)) | G41: =IF($A41="","",INDEX(Purchase_Orders!$N$2:$N$301,$A41)) | H41: =IF($A41="","",INDEX(Purchase_Orders!$F$2:$F$301,$A41)) | I41: =IF($A41="","",INDEX(Purchase_Orders!$G$2:$G$301,$A41)) | J41: =IF($A41="","",INDEX(Purchase_Orders!$H$2:$H$301,$A41)&"") | K41: =IF($A41="","",IF(INDEX(Purchase_Orders!$P$2:$P$301,$A41)=1,"Yes","")) | L41: =IF($A41="","",INDEX(Purchase_Orders!$Q$2:$Q$301,$A41))
A42: =IFERROR(MATCH(8,Purchase_Orders!$T$2:$T$301,0),"") | B42: =IF($A42="","",INDEX(Purchase_Orders!$A$2:$A$301,$A42)&"") | C42: =IF($A42="","",INDEX(Purchase_Orders!$K$2:$K$301,$A42)&"") | D42: =IF($A42="","",INDEX(Purchase_Orders!$C$2:$C$301,$A42)&"") | E42: =IF($A42="","",INDEX(Purchase_Orders!$D$2:$D$301,$A42)) | F42: =IF($A42="","",INDEX(Purchase_Orders!$M$2:$M$301,$A42)) | G42: =IF($A42="","",INDEX(Purchase_Orders!$N$2:$N$301,$A42)) | H42: =IF($A42="","",INDEX(Purchase_Orders!$F$2:$F$301,$A42)) | I42: =IF($A42="","",INDEX(Purchase_Orders!$G$2:$G$301,$A42)) | J42: =IF($A42="","",INDEX(Purchase_Orders!$H$2:$H$301,$A42)&"") | K42: =IF($A42="","",IF(INDEX(Purchase_Orders!$P$2:$P$301,$A42)=1,"Yes","")) | L42: =IF($A42="","",INDEX(Purchase_Orders!$Q$2:$Q$301,$A42))
A43: =IFERROR(MATCH(9,Purchase_Orders!$T$2:$T$301,0),"") | B43: =IF($A43="","",INDEX(Purchase_Orders!$A$2:$A$301,$A43)&"") | C43: =IF($A43="","",INDEX(Purchase_Orders!$K$2:$K$301,$A43)&"") | D43: =IF($A43="","",INDEX(Purchase_Orders!$C$2:$C$301,$A43)&"") | E43: =IF($A43="","",INDEX(Purchase_Orders!$D$2:$D$301,$A43)) | F43: =IF($A43="","",INDEX(Purchase_Orders!$M$2:$M$301,$A43)) | G43: =IF($A43="","",INDEX(Purchase_Orders!$N$2:$N$301,$A43)) | H43: =IF($A43="","",INDEX(Purchase_Orders!$F$2:$F$301,$A43)) | I43: =IF($A43="","",INDEX(Purchase_Orders!$G$2:$G$301,$A43)) | J43: =IF($A43="","",INDEX(Purchase_Orders!$H$2:$H$301,$A43)&"") | K43: =IF($A43="","",IF(INDEX(Purchase_Orders!$P$2:$P$301,$A43)=1,"Yes","")) | L43: =IF($A43="","",INDEX(Purchase_Orders!$Q$2:$Q$301,$A43))
A44: =IFERROR(MATCH(10,Purchase_Orders!$T$2:$T$301,0),"") | B44: =IF($A44="","",INDEX(Purchase_Orders!$A$2:$A$301,$A44)&"") | C44: =IF($A44="","",INDEX(Purchase_Orders!$K$2:$K$301,$A44)&"") | D44: =IF($A44="","",INDEX(Purchase_Orders!$C$2:$C$301,$A44)&"") | E44: =IF($A44="","",INDEX(Purchase_Orders!$D$2:$D$301,$A44)) | F44: =IF($A44="","",INDEX(Purchase_Orders!$M$2:$M$301,$A44)) | G44: =IF($A44="","",INDEX(Purchase_Orders!$N$2:$N$301,$A44)) | H44: =IF($A44="","",INDEX(Purchase_Orders!$F$2:$F$301,$A44)) | I44: =IF($A44="","",INDEX(Purchase_Orders!$G$2:$G$301,$A44)) | J44: =IF($A44="","",INDEX(Purchase_Orders!$H$2:$H$301,$A44)&"") | K44: =IF($A44="","",IF(INDEX(Purchase_Orders!$P$2:$P$301,$A44)=1,"Yes","")) | L44: =IF($A44="","",INDEX(Purchase_Orders!$Q$2:$Q$301,$A44))
...

Sheet Config
A1: Config: settings, lists and import checks
A2: White cells can be changed. Every formula in the workbook reads these settings and lists.
A3: Setting | B3: Value | C3: What it does
A4: As-of date | B4: 46310 | C4: All day counts, overdue flags and expiry windows use this date. Change it to see the workbook on another day.
A5: Opening balance date | B5: 46204 | C5: Opening balances in Products and Batches are the units on hand on this date.
A6: Expiry window 1 (days) | B6: 30 | C6: First expiry window ends at this many days left.
A7: Expiry window 2 (days) | B7: 60 | C7: Second expiry window ends here.
A8: Expiry window 3 (days) | B8: 90 | C8: Third expiry window ends here. Lots beyond it are not alerted.
A9: Reorder test uses | B9: Available | C9: Available or Recorded: which stock is compared with the reorder point.
A10: Expired lots are held | B10: Yes | C10: Yes = units in expired lots are not available.
A11: File in Import_Staging | B11: warehouse-movements-2026-10-14.csv | C11: Name of the file now pasted in Import_Staging.
A13: Lists for dropdowns and rules. Add new values in the empty white cells under a list.
A14: Movement types | B14: Adjustment reasons | C14: PO statuses | D14: PO counts as open | E14: Lot statuses | F14: Lot holds stock | G14: Lot allowed on receipt | H14: Reservation statuses | I14: Reservation holds stock | J14: Task statuses | K14: Task counts as open | L14: Supplier types | M14: Supplier statuses | N14: Product categories | O14: Product statuses | P14: Campaign statuses | Q14: Channels | R14: Priorities | S14: Document types | T14: Document statuses | U14: Milestone kinds | V14: Milestone statuses | W14: Yes/No | X14: Reorder basis
A15: Receipt | B15: Cycle count | C15: Draft | D15: No | E15: Released | F15: No | G15: Yes | H15: Active | I15: Yes | J15: Not started | K15: Yes | L15: Manufacturer | M15: Active | N15: Whey protein | O15: Active | P15: Draft | Q15: Paid social | R15: High | S15: Spec sheet | T15: Current | U15: Product | V15: Planned | W15: Yes | X15: Available
A16: Shipment | B16: Damaged in warehouse | C16: Ordered | D16: Yes | E16: Quarantine | F16: Yes | G16: Yes | H16: Pending | I16: No | J16: In progress | K16: Yes | L16: Co-packer | M16: On hold | N16: Plant protein | O16: Discontinued | P16: In review | Q16: Short-form video | R16: Medium | S16: Certificate of analysis | T16: In review | U16: Campaign | V16: On track | W16: No | X16: Recorded
A17: Adjustment | B17: Expired write-off | C17: Confirmed | D17: Yes | E17: On hold | F17: Yes | G17: Yes | H17: Released | I17: No | J17: Blocked | K17: Yes | L17: Ingredient supplier | M17: Inactive | N17: Casein | P17: Approved | Q17: Email | R17: Low | S17: Label artwork | T17: Superseded | V17: At risk
B18: Marketing samples | C18: In transit | D18: Yes | E18: Closed | F18: No | G18: No | H18: Cancelled | I18: No | J18: Done | K18: No | L18: 3PL | N18: Protein bars | P18: Live | Q18: Influencer | S18: Agreement | V18: Late
B19: Customer return | C19: Partially received | D19: Yes | J19: Cancelled | K19: No | N19: Creatine | P19: Completed | Q19: Marketplace ads | S19: Allergen statement | V19: Done
B20: Other | C20: Received | D20: No | N20: Pre-workout | P20: Cancelled | Q20: Search ads | S20: SOP
C21: Cancelled | D21: No | Q21: Retail promotion | S21: Insurance certificate
Q22: Affiliate | S22: Campaign brief
A37: Import checks run on every Import_Staging row (catalog read by the formulas; do not reorder)
A38: # | B38: Code | C38: Field | D38: Issue | E38: Applies to | F38: What to do
A39: 1 | B39: ID_MISSING | C39: movement_id | D39: Missing required field | E39: All rows | F39: Add a unique movement_id.
A40: 2 | B40: ID_DUP_FILE | C40: movement_id | D40: Duplicate ID | E40: All rows | F40: Give the row its own ID, or delete it if it repeats an earlier row.
A41: 3 | B41: ID_DUP_LEDGER | C41: movement_id | D41: Duplicate ID | E41: All rows | F41: Delete the row if it was posted before; a new movement needs a new ID.
A42: 4 | B42: DATE_MISSING | C42: date | D42: Missing required field | E42: All rows | F42: Add the movement date (yyyy-mm-dd).
A43: 5 | B43: DATE_INVALID | C43: date | D43: Invalid date | E43: All rows | F43: Fix the date (yyyy-mm-dd).
A44: 6 | B44: DATE_FUTURE | C44: date | D44: Invalid date | E44: All rows | F44: Check the date; a movement cannot be after the as-of date.
A45: 7 | B45: TYPE_MISSING | C45: type | D45: Missing required field | E45: All rows | F45: Add the type: Receipt, Shipment or Adjustment.
A46: 8 | B46: TYPE_UNSUPPORTED | C46: type | D46: Unsupported type | E46: All rows | F46: Use a movement type listed on Config.
A47: 9 | B47: SKU_MISSING | C47: sku | D47: Missing required field | E47: All rows | F47: Add the SKU.
A48: 10 | B48: SKU_UNKNOWN | C48: sku | D48: Unknown product | E48: All rows | F48: Add the product in Products first, or correct the SKU.
A49: 11 | B49: SUP_MISSING | C49: supplier_id | D49: Missing required field | E49: Receipts | F49: Add the supplier ID.
A50: 12 | B50: SUP_UNKNOWN | C50: supplier_id | D50: Unknown supplier | E50: Rows with a supplier_id | F50: Add the supplier in Suppliers first, or correct the ID.
... A61: 23 | B61: NEG_STOCK | C61: qty | D61: Negative inventory | E61: Rows that change stock | F61: Check the quantity and sign against the warehouse count before posting.

Sheet Products
A1: SKU * | B1: Product name * | C1: Category * | D1: Flavour | E1: Size | F1: Primary supplier ID * | G1: Unit cost (USD) | H1: Opening balance * | I1: Reorder point * | J1: Reorder qty * | K1: Shelf life (months) | L1: Status * | M1: Notes | N1: Supplier name | O1: Receipts | P1: Shipments | Q1: Adjustments | R1: Recorded stock | S1: Reserved | T1: Held in lots | U1: Available | V1: On order (open POs) | W1: Lot balances total | X1: Lot openings total | Y1: Below reorder (1 = yes) | Z1: Stock status | AA1: Stock value (USD) | AB1: Record check | AC1: Alert order
A2: WPI-CHO-2LB | B2: Whey Protein Isolate, Chocolate, 2 lb | C2: Whey protein | D2: Chocolate | E2: 2 lb | F2: SUP-01 | G2: 18.4 | H2: 1240 | I2: 600 | J2: 1500 | K2: 24 | L2: Active | N2: =IF($A2="","",IFERROR(INDEX(Suppliers!$B$2:$B$51,MATCH($F2,Suppliers!$A$2:$A$51,0))&"","(not found)")) -> Alder Creek Dairy Proteins | O2: =IF($A2="","",SUMIFS(Inventory_Ledger!$E$2:$E$2001,Inventory_Ledger!$D$2:$D$2001,$A2,Inventory_Ledger!$C$2:$C$2001,"Receipt")) -> 1500 | P2: =IF($A2="","",SUMIFS(Inventory_Ledger!$E$2:$E$2001,Inventory_Ledger!$D$2:$D$2001,$A2,Inventory_Ledger!$C$2:$C$2001,"Shipment")) -> 2305 | Q2: =IF($A2="","",SUMIFS(Inventory_Ledger!$E$2:$E$2001,Inventory_Ledger!$D$2:$D$2001,$A2,Inventory_Ledger!$C$2:$C$2001,"Adjustment")) -> -6 | R2: =IF($A2="","",IF(ISNUMBER($H2),$H2,0)+$O2-$P2+$Q2) -> 429 | S2: =IF($A2="","",SUMIFS(Reservations!$L$2:$L$201,Reservations!$B$2:$B$201,$A2)) -> 120 | T2: =IF($A2="","",SUMIFS(Batches!$P$2:$P$301,Batches!$B$2:$B$301,$A2)) -> 0 | U2: =IF($A2="","",$R2-$S2-$T2) -> 309 | V2: =IF($A2="","",SUMIFS(Purchase_Orders!$N$2:$N$301,Purchase_Orders!$C$2:$C$301,$A2,Purchase_Orders!$O$2:$O$301,1)) -> 1500 | W2: =IF($A2="","",SUMIFS(Batches!$L$2:$L$301,Batches!$B$2:$B$301,$A2)) -> 429 | X2: =IF($A2="","",SUMIFS(Batches!$F$2:$F$301,Batches!$B$2:$B$301,$A2)) -> 1240 | Y2: =IF($A2="","",IF(ISNUMBER($I2),IF(IF(Config!$B$9="Recorded",$R2,$U2)<$I2,1,0),0)) -> 1 | Z2: =IF($A2="","",IF($R2<0,"Negative",IF($Y2=1,"Below reorder","OK"))) -> Below reorder | AA2: =IF($A2="","",IF(ISNUMBER($G2),$R2*$G2,"")) -> 7893.6 | AB2: =IF(COUNTA($A2:$M2)=0,"",IF($A2="","Missing: SKU",IF(COUNTIF($A$2:$A$101,$A2)>1,"Duplicate SKU",IF($B2="","Missing: product name",IF($C2="","Missing: category",IF($F2="","Missing: primary supplier",IF(NOT(ISNUMBER($H2)),"Missing: opening balance",IF(NOT(ISNUMBER($I2)),"Missing: reorder point",IF(NOT(ISNUMBER($J2)),"Missing: reorder qty",IF($L2="","Missing: status",IF(COUNTIF(Suppliers!$A$2:$A$51,$F2)=0,"Unknown supplier",IF(COUNTIF(Config!$N$15:$N$34,$C2)=0,"Unsupported category",IF(COUNTIF(Config!$O$15:$O$34,$L2)=0,"Unsupported status",IF($X2<>$H2,"Opening balance differs from lot openings",IF($W2<>$R2,"Lot balances differ from recorded stock",IF($R2<0,"Negative recorded stock","OK")))))))))))))))) -> OK | AC2: =IF($Y2=1,COUNTIF($Y$2:$Y2,1),"") -> 1
A3: WPI-VAN-2LB | B3: Whey Protein Isolate, Vanilla, 2 lb | C3: Whey protein | D3: Vanilla | E3: 2 lb | F3: SUP-01 | G3: 18.4 | H3: 846 | I3: 450 | J3: 1200 | K3: 24 | L3: Active | N3: =IF($A3="","",IFERROR(INDEX(Suppliers!$B$2:$B$51,MATCH($F3,Suppliers!$A$2:$A$51,0))&"","(not found)")) -> Alder Creek Dairy Proteins | O3: =IF($A3="","",SUMIFS(Inventory_Ledger!$E$2:$E$2001,Inventory_Ledger!$D$2:$D$2001,$A3,Inventory_Ledger!$C$2:$C$2001,"Receipt")) -> 600 | P3: =IF($A3="","",SUMIFS(Inventory_Ledger!$E$2:$E$2001,Inventory_Ledger!$D$2:$D$2001,$A3,Inventory_Ledger!$C$2:$C$2001,"Shipment")) -> 638 | Q3: =IF($A3="","",SUMIFS(Inventory_Ledger!$E$2:$E$2001,Inventory_Ledger!$D$2:$D$2001,$A3,Inventory_Ledger!$C$2:$C$2001,"Adjustment")) -> 0 | R3: =IF($A3="","",IF(ISNUMBER($H3),$H3,0)+$O3-$P3+$Q3) -> 808 | S3: =IF($A3="","",SUMIFS(Reservations!$L$2:$L$201,Reservations!$B$2:$B$201,$A3)) -> 0 | T3: =IF($A3="","",SUMIFS(Batches!$P$2:$P$301,Batches!$B$2:$B$301,$A3)) -> 600 | U3: =IF($A3="","",$R3-$S3-$T3) -> 208 | V3: =IF($A3="","",SUMIFS(Purchase_Orders!$N$2:$N$301,Purchase_Orders!$C$2:$C$301,$A3,Purchase_Orders!$O$2:$O$301,1)) -> 600 | W3: =IF($A3="","",SUMIFS(Batches!$L$2:$L$301,Batches!$B$2:$B$301,$A3)) -> 808 | X3: =IF($A3="","",SUMIFS(Batches!$F$2:$F$301,Batches!$B$2:$B$301,$A3)) -> 846 | Y3: =IF($A3="","",IF(ISNUMBER($I3),IF(IF(Config!$B$9="Recorded",$R3,$U3)<$I3,1,0),0)) -> 1 | Z3: =IF($A3="","",IF($R3<0,"Negative",IF($Y3=1,"Below reorder","OK"))) -> Below reorder | AA3: =IF($A3="","",IF(ISNUMBER($G3),$R3*$G3,"")) -> 14867.2 | AB3: =IF(COUNTA($A3:$M3)=0,"",IF($A3="","Missing: SKU",IF(COUNTIF($A$2:$A$101,$A3)>1,"Duplicate SKU",IF($B3="","Missing: product name",IF($C3="","Missing: category",IF($F3="","Missing: primary supplier",IF(NOT(ISNUMBER($H3)),"Missing: opening balance",IF(NOT(ISNUMBER($I3)),"Missing: reorder point",IF(NOT(ISNUMBER($J3)),"Missing: reorder qty",IF($L3="","Missing: status",IF(COUNTIF(Suppliers!$A$2:$A$51,$F3)=0,"Unknown supplier",IF(COUNTIF(Config!$N$15:$N$34,$C3)=0,"Unsupported category",IF(COUNTIF(Config!$O$15:$O$34,$L3)=0,"Unsupported status",IF($X3<>$H3,"Opening balance differs from lot openings",IF($W3<>$R3,"Lot balances differ from recorded stock",IF($R3<0,"Negative recorded stock","OK")))))))))))))))) -> OK | AC3: =IF($Y3=1,COUNTIF($Y$2:$Y3,1),"") -> 2
A4: WPI-CHO-5LB | B4: Whey Protein Isolate, Chocolate, 5 lb | C4: Whey protein | D4: Chocolate | E4: 5 lb | F4: SUP-05 | G4: 39.8 | H4: 467 | I4: 150 | J4: 400 | K4: 24 | L4: Active | N4: =IF($A4="","",IFERROR(INDEX(Suppliers!$B$2:$B$51,MATCH($F4,Suppliers!$A$2:$A$51,0))&"","(not found)")) -> Elmstead Co-Packing | O4: =IF($A4="","",SUMIFS(Inventory_Ledger!$E$2:$E$2001,Inventory_Ledger!$D$2:$D$2001,$A4,Inventory_Ledger!$C$2:$C$2001,"Receipt")) -> 0 | P4: =IF($A4="","",SUMIFS(Inventory_Ledger!$E$2:$E$2001,Inventory_Ledger!$D$2:$D$2001,$A4,Inventory_Ledger!$C$2:$C$2001,"Shipment")) -> 203 | Q4: =IF($A4="","",SUMIFS(Inventory_Ledger!$E$2:$E$2001,Inventory_Ledger!$D$2:$D$2001,$A4,Inventory_Ledger!$C$2:$C$2001,"Adjustment")) -> 0 | R4: =IF($A4="","",IF(ISNUMBER($H4),$H4,0)+$O4-$P4+$Q4) -> 264 | S4: =IF($A4="","",SUMIFS(Reservations!$L$2:$L$201,Reservations!$B$2:$B$201,$A4)) -> 0 | T4: =IF($A4="","",SUMIFS(Batches!$P$2:$P$301,Batches!$B$2:$B$301,$A4)) -> 0 | U4: =IF($A4="","",$R4-$S4-$T4) -> 264 | V4: =IF($A4="","",SUMIFS(Purchase_Orders!$N$2:$N$301,Purchase_Orders!$C$2:$C$301,$A4,Purchase_Orders!$O$2:$O$301,1)) -> 0 | W4: =IF($A4="","",SUMIFS(Batches!$L$2:$L$301,Batches!$B$2:$B$301,$A4)) -> 264 | X4: =IF($A4="","",SUMIFS(Batches!$F$2:$F$301,Batches!$B$2:$B$301,$A4)) -> 467 | Y4: =IF($A4="","",IF(ISNUMBER($I4),IF(IF(Config!$B$9="Recorded",$R4,$U4)<$I4,1,0),0)) -> 0 | Z4: =IF($A4="","",IF($R4<0,"Negative",IF($Y4=1,"Below reorder","OK"))) -> OK | AA4: =IF($A4="","",IF(ISNUMBER($G4),$R4*$G4,"")) -> 10507.2 | AB4: =IF(COUNTA($A4:$M4)=0,"",IF($A4="","Missing: SKU",IF(COUNTIF($A$2:$A$101,$A4)>1,"Duplicate SKU",IF($B4="","Missing: product name",IF($C4="","Missing: category",IF($F4="","Missing: primary supplier",IF(NOT(ISNUMBER($H4)),"Missing: opening balance",IF(NOT(ISNUMBER($I4)),"Missing: reorder point",IF(NOT(ISNUMBER($J4)),"Missing: reorder qty",IF($L4="","Missing: status",IF(COUNTIF(Suppliers!$A$2:$A$51,$F4)=0,"Unknown supplier",IF(COUNTIF(Config!$N$15:$N$34,$C4)=0,"Unsupported category",IF(COUNTIF(Config!$O$15:$O$34,$L4)=0,"Unsupported status",IF($X4<>$H4,"Opening balance differs from lot openings",IF($W4<>$R4,"Lot balances differ from recorded stock",IF($R4<0,"Negative recorded stock","OK")))))))))))))))) -> OK | AC4: =IF($Y4=1,COUNTIF($Y$2:$Y4,1),"")
A5: PLT-CHO-2LB | B5: Plant Protein, Chocolate, 2 lb | C5: Plant protein | D5: Chocolate | E5: 2 lb | F5: SUP-03 | G5: 16.1 | H5: 850 | I5: 250 | J5: 600 | K5: 24 | L5: Active | N5: =IF($A5="","",IFERROR(INDEX(Suppliers!$B$2:$B$51,MATCH($F5,Suppliers!$A$2:$A$51,0))&"","(not found)")) -> Corliss Plant Proteins | O5: =IF($A5="","",SUMIFS(Inventory_Ledger!$E$2:$E$2001,Inventory_Ledger!$D$2:$D$2001,$A5,Inventory_Ledger!$C$2:$C$2001,"Receipt")) -> 0 | P5: =IF($A5="","",SUMIFS(Inventory_Ledger!$E$2:$E$2001,Inventory_Ledger!$D$2:$D$2001,$A5,Inventory_Ledger!$C$2:$C$2001,"Shipment")) -> 451 | Q5: =IF($A5="","",SUMIFS(Inventory_Ledger!$E$2:$E$2001,Inventory_Ledger!$D$2:$D$2001,$A5,Inventory_Ledger!$C$2:$C$2001,"Adjustment")) -> -3 | R5: =IF($A5="","",IF(ISNUMBER($H5),$H5,0)+$O5-$P5+$Q5) -> 396 | S5: =IF($A5="","",SUMIFS(Reservations!$L$2:$L$201,Reservations!$B$2:$B$201,$A5)) -> 0 | T5: =IF($A5="","",SUMIFS(Batches!$P$2:$P$301,Batches!$B$2:$B$301,$A5)) -> 0 | U5: =IF($A5="","",$R5-$S5-$T5) -> 396 | V5: =IF($A5="","",SUMIFS(Purchase_Orders!$N$2:$N$301,Purchase_Orders!$C$2:$C$301,$A5,Purchase_Orders!$O$2:$O$301,1)) -> 0 | W5: =IF($A5="","",SUMIFS(Batches!$L$2:$L$301,Batches!$B$2:$B$301,$A5)) -> 396 | X5: =IF($A5="","",SUMIFS(Batches!$F$2:$F$301,Batches!$B$2:$B$301,$A5)) -> 850 | Y5: =IF($A5="","",IF(ISNUMBER($I5),IF(IF(Config!$B$9="Recorded",$R5,$U5)<$I5,1,0),0)) -> 0 | Z5: =IF($A5="","",IF($R5<0,"Negative",IF($Y5=1,"Below reorder","OK"))) -> OK | AA5: =IF($A5="","",IF(ISNUMBER($G5),$R5*$G5,"")) -> 6375.6 | AB5: =IF(COUNTA($A5:$M5)=0,"",IF($A5="","Missing: SKU",IF(COUNTIF($A$2:$A$101,$A5)>1,"Duplicate SKU",IF($B5="","Missing: product name",IF($C5="","Missing: category",IF($F5="","Missing: primary supplier",IF(NOT(ISNUMBER($H5)),"Missing: opening balance",IF(NOT(ISNUMBER($I5)),"Missing: reorder point",IF(NOT(ISNUMBER($J5)),"Missing: reorder qty",IF($L5="","Missing: status",IF(COUNTIF(Suppliers!$A$2:$A$51,$F5)=0,"Unknown supplier",IF(COUNTIF(Config!$N$15:$N$34,$C5)=0,"Unsupported category",IF(COUNTIF(Config!$O$15:$O$34,$L5)=0,"Unsupported status",IF($X5<>$H5,"Opening balance differs from lot openings",IF($W5<>$R5,"Lot balances differ from recorded stock",IF($R5<0,"Negative recorded stock","OK")))))))))))))))) -> OK | AC5: =IF($Y5=1,COUNTIF($Y$2:$Y5,1),"")
A6: PLT-VAN-2LB | B6: Plant Protein, Vanilla, 2 lb | C6: Plant protein | D6: Vanilla | E6: 2 lb | F6: SUP-03 | G6: 16.1 | H6: 407 | I6: 200 | J6: 500 | K6: 24 | L6: Active | N6: =IF($A6="","",IFERROR(INDEX(Suppliers!$B$2:$B$51,MATCH($F6,Suppliers!$A$2:$A$51,0))&"","(not found)")) -> Corliss Plant Proteins | O6: =IF($A6="","",SUMIFS(Inventory_Ledger!$E$2:$E$2001,Inventory_Ledger!$D$2:$D$2001,$A6,Inventory_Ledger!$C$2:$C$2001,"Receipt")) -> 0 | P6: =IF($A6="","",SUMIFS(Inventory_Ledger!$E$2:$E$2001,Inventory_Ledger!$D$2:$D$2001,$A6,Inventory_Ledger!$C$2:$C$2001,"Shipment")) -> 274 | Q6: =IF($A6="","",SUMIFS(Inventory_Ledger!$E$2:$E$2001,Inventory_Ledger!$D$2:$D$2001,$A6,Inventory_Ledger!$C$2:$C$2001,"Adjustment")) -> 0 | R6: =IF($A6="","",IF(ISNUMBER($H6),$H6,0)+$O6-$P6+$Q6) -> 133 | S6: =IF($A6="","",SUMIFS(Reservations!$L$2:$L$201,Reservations!$B$2:$B$201,$A6)) -> 0 | T6: =IF($A6="","",SUMIFS(Batches!$P$2:$P$301,Batches!$B$2:$B$301,$A6)) -> 0 | U6: =IF($A6="","",$R6-$S6-$T6) -> 133 | V6: =IF($A6="","",SUMIFS(Purchase_Orders!$N$2:$N$301,Purchase_Orders!$C$2:$C$301,$A6,Purchase_Orders!$O$2:$O$301,1)) -> 500 | W6: =IF($A6="","",SUMIFS(Batches!$L$2:$L$301,Batches!$B$2:$B$301,$A6)) -> 133 | X6: =IF($A6="","",SUMIFS(Batches!$F$2:$F$301,Batches!$B$2:$B$301,$A6)) -> 407 | Y6: =IF($A6="","",IF(ISNUMBER($I6),IF(IF(Config!$B$9="Recorded",$R6,$U6)<$I6,1,0),0)) -> 1 | Z6: =IF($A6="","",IF($R6<0,"Negative",IF($Y6=1,"Below reorder","OK"))) -> Below reorder | AA6: =IF($A6="","",IF(ISNUMBER($G6),$R6*$G6,"")) -> 2141.3 | AB6: =IF(COUNTA($A6:$M6)=0,"",IF($A6="","Missing: SKU",IF(COUNTIF($A$2:$A$101,$A6)>1,"Duplicate SKU",IF($B6="","Missing: product name",IF($C6="","Missing: category",IF($F6="","Missing: primary supplier",IF(NOT(ISNUMBER($H6)),"Missing: opening balance",IF(NOT(ISNUMBER($I6)),"Missing: reorder point",IF(NOT(ISNUMBER($J6)),"Missing: reorder qty",IF($L6="","Missing: status",IF(COUNTIF(Suppliers!$A$2:$A$51,$F6)=0,"Unknown supplier",IF(COUNTIF(Config!$N$15:$N$34,$C6)=0,"Unsupported category",IF(COUNTIF(Config!$O$15:$O$34,$L6)=0,"Unsupported status",IF($X6<>$H6,"Opening balance differs from lot openings",IF($W6<>$R6,"Lot balances differ from recorded stock",IF($R6<0,"Negative recorded stock","OK")))))))))))))))) -> OK | AC6: =IF($Y6=1,COUNTIF($Y$2:$Y6,1),"") -> 3
A7: BAR-PBC-12 | B7: Protein Bar, Peanut Butter Chocolate, 12-pack | C7: Protein bars | D7: Peanut butter chocolate | E7: 12-pack | F7: SUP-02 | G7: 11.2 | H7: 2288 | I7: 900 | J7: 2400 | K7: 12 | L7: Active | N7: =IF($A7="","",IFERROR(INDEX(Suppliers!$B$2:$B$51,MATCH($F7,Suppliers!$A$2:$A$51,0))&"","(not found)")) -> Bramwell Bar Works | O7: =IF($A7="","",SUMIFS(Inventory_Ledger!$E$2:$E$2001,Inventory_Ledger!$D$2:$D$2001,$A7,Inventory_Ledger!$C$2:$C$2001,"Receipt")) -> 2400 | P7: =IF($A7="","",SUMIFS(Inventory_Ledger!$E$2:$E$2001,Inventory_Ledger!$D$2:$D$2001,$A7,Inventory_Ledger!$C$2:$C$2001,"Shipment")) -> 1944 | Q7: =IF($A7="","",SUMIFS(Inventory_Ledger!$E$2:$E$2001,Inventory_Ledger!$D$2:$D$2001,$A7,Inventory_Ledger!$C$2:$C$2001,"Adjustment")) -> 0 | R7: =IF($A7="","",IF(ISNUMBER($H7),$H7,0)+$O7-$P7+$Q7) -> 2744 | S7: =IF($A7="","",SUMIFS(Reservations!$L$2:$L$201,Reservations!$B$2:$B$201,$A7)) -> 200 | T7: =IF($A7="","",SUMIFS(Batches!$P$2:$P$301,Batches!$B$2:$B$301,$A7)) -> 0 | U7: =IF($A7="","",$R7-$S7-$T7) -> 2544 | V7: =IF($A7="","",SUMIFS(Purchase_Orders!$N$2:$N$301,Purchase_Orders!$C$2:$C$301,$A7,Purchase_Orders!$O$2:$O$301,1)) -> 0 | W7: =IF($A7="","",SUMIFS(Batches!$L$2:$L$301,Batches!$B$2:$B$301,$A7)) -> 2744 | X7: =IF($A7="","",SUMIFS(Batches!$F$2:$F$301,Batches!$B$2:$B$301,$A7)) -> 2288 | Y7: =IF($A7="","",IF(ISNUMBER($I7),IF(IF(Config!$B$9="Recorded",$R7,$U7)<$I7,1,0),0)) -> 0 | Z7: =IF($A7="","",IF($R7<0,"Negative",IF($Y7=1,"Below reorder","OK"))) -> OK | AA7: =IF($A7="","",IF(ISNUMBER($G7),$R7*$G7,"")) -> 30732.8 | AB7: =IF(COUNTA($A7:$M7)=0,"",IF($A7="","Missing: SKU",IF(COUNTIF($A$2:$A$101,$A7)>1,"Duplicate SKU",IF($B7="","Missing: product name",IF($C7="","Missing: category",IF($F7="","Missing: primary supplier",IF(NOT(ISNUMBER($H7)),"Missing: opening balance",IF(NOT(ISNUMBER($I7)),"Missing: reorder point",IF(NOT(ISNUMBER($J7)),"Missing: reorder qty",IF($L7="","Missing: status",IF(COUNTIF(Suppliers!$A$2:$A$51,$F7)=0,"Unknown supplier",IF(COUNTIF(Config!$N$15:$N$34,$C7)=0,"Unsupported category",IF(COUNTIF(Config!$O$15:$O$34,$L7)=0,"Unsupported status",IF($X7<>$H7,"Opening balance differs from lot openings",IF($W7<>$R7,"Lot balances differ from recorded stock",IF($R7<0,"Negative recorded stock","OK")))))))))))))))) -> OK | AC7: =IF($Y7=1,COUNTIF($Y$2:$Y7,1),"")
A8: BAR-CKD-12 | B8: Protein Bar, Cookie Dough, 12-pack | C8: Protein bars | D8: Cookie dough | E8: 12-pack | F8: SUP-02 | G8: 11.2 | H8: 1889 | I8: 700 | J8: 1500 | K8: 12 | L8: Active | N8: =IF($A8="","",IFERROR(INDEX(Suppliers!$B$2:$B$51,MATCH($F8,Suppliers!$A$2:$A$51,0))&"","(not found)")) -> Bramwell Bar Works | O8: =IF($A8="","",SUMIFS(Inventory_Ledger!$E$2:$E$2001,Inventory_Ledger!$D$2:$D$2001,$A8,Inventory_Ledger!$C$2:$C$2001,"Receipt")) -> 1500 | P8: =IF($A8="","",SUMIFS(Inventory_Ledger!$E$2:$E$2001,Inventory_Ledger!$D$2:$D$2001,$A8,Inventory_Ledger!$C$2:$C$2001,"Shipment")) -> 1581 | Q8: =IF($A8="","",SUMIFS(Inventory_Ledger!$E$2:$E$2001,Inventory_Ledger!$D$2:$D$2001,$A8,Inventory_Ledger!$C$2:$C$2001,"Adjustment")) -> -60 | R8: =IF($A8="","",IF(ISNUMBER($H8),$H8,0)+$O8-$P8+$Q8) -> 1748 | S8: =IF($A8="","",SUMIFS(Reservations!$L$2:$L$201,Reservations!$B$2:$B$201,$A8)) -> 150 | T8: =IF($A8="","",SUMIFS(Batches!$P$2:$P$301,Batches!$B$2:$B$301,$A8)) -> 36 | U8: =IF($A8="","",$R8-$S8-$T8) -> 1562 | V8: =IF($A8="","",SUMIFS(Purchase_Orders!$N$2:$N$301,Purchase_Orders!$C$2:$C$301,$A8,Purchase_Orders!$O$2:$O$301,1)) -> 0 | W8: =IF($A8="","",SUMIFS(Batches!$L$2:$L$301,Batches!$B$2:$B$301,$A8)) -> 1748 | X8: =IF($A8="","",SUMIFS(Batches!$F$2:$F$301,Batches!$B$2:$B$301,$A8)) -> 1889 | Y8: =IF($A8="","",IF(ISNUMBER($I8),IF(IF(Config!$B$9="Recorded",$R8,$U8)<$I8,1,0),0)) -> 0 | Z8: =IF($A8="","",IF($R8<0,"Negative",IF($Y8=1,"Below reorder","OK"))) -> OK | AA8: =IF($A8="","",IF(ISNUMBER($G8),$R8*$G8,"")) -> 19577.6 | AB8: =IF(COUNTA($A8:$M8)=0,"",IF($A8="","Missing: SKU",IF(COUNTIF($A$2:$A$101,$A8)>1,"Duplicate SKU",IF($B8="","Missing: product name",IF($C8="","Missing: category",IF($F8="","Missing: primary supplier",IF(NOT(ISNUMBER($H8)),"Missing: opening balance",IF(NOT(ISNUMBER($I8)),"Missing: reorder point",IF(NOT(ISNUMBER($J8)),"Missing: reorder qty",IF($L8="","Missing: status",IF(COUNTIF(Suppliers!$A$2:$A$51,$F8)=0,"Unknown supplier",IF(COUNTIF(Config!$N$15:$N$34,$C8)=0,"Unsupported category",IF(COUNTIF(Config!$O$15:$O$34,$L8)=0,"Unsupported status",IF($X8<>$H8,"Opening balance differs from lot openings",IF($W8<>$R8,"Lot balances differ from recorded stock",IF($R8<0,"Negative recorded stock","OK")))))))))))))))) -> OK | AC8: =IF($Y8=1,COUNTIF($Y$2:$Y8,1),"")
A9: CRE-UNF-300G | B9: Creatine Monohydrate, Unflavoured, 300 g | C9: Creatine | D9: Unflavoured | E9: 300 g | F9: SUP-04 | G9: 6.9 | H9: 980 | I9: 400 | J9: 1000 | K9: 36 | L9: Active | N9: =IF($A9="","",IFERROR(INDEX(Suppliers!$B$2:$B$51,MATCH($F9,Suppliers!$A$2:$A$51,0))&"","(not found)")) -> Dunmore Powder Labs | O9: =IF($A9="","",SUMIFS(Inventory_Ledger!$E$2:$E$2001,Inventory_Ledger!$D$2:$D$2001,$A9,Inventory_Ledger!$C$2:$C$2001,"Receipt")) -> 1000 | P9: =IF($A9="","",SUMIFS(Inventory_Ledger!$E$2:$E$2001,Inventory_Ledger!$D$2:$D$2001,$A9,Inventory_Ledger!$C$2:$C$2001,"Shipment")) -> 865 | Q9: =IF($A9="","",SUMIFS(Inventory_Ledger!$E$2:$E$2001,Inventory_Ledger!$D$2:$D$2001,$A9,Inventory_Ledger!$C$2:$C$2001,"Adjustment")) -> 4 | R9: =IF($A9="","",IF(ISNUMBER($H9),$H9,0)+$O9-$P9+$Q9) -> 1119 | S9: =IF($A9="","",SUMIFS(Reservations!$L$2:$L$201,Reservations!$B$2:$B$201,$A9)) -> 0 | T9: =IF($A9="","",SUMIFS(Batches!$P$2:$P$301,Batches!$B$2:$B$301,$A9)) -> 0 | U9: =IF($A9="","",$R9-$S9-$T9) -> 1119 | V9: =IF($A9="","",SUMIFS(Purchase_Orders!$N$2:$N$301,Purchase_Orders!$C$2:$C$301,$A9,Purchase_Orders!$O$2:$O$301,1)) -> 0 | W9: =IF($A9="","",SUMIFS(Batches!$L$2:$L$301,Batches!$B$2:$B$301,$A9)) -> 1119 | X9: =IF($A9="","",SUMIFS(Batches!$F$2:$F$301,Batches!$B$2:$B$301,$A9)) -> 980 | Y9: =IF($A9="","",IF(ISNUMBER($I9),IF(IF(Config!$B$9="Recorded",$R9,$U9)<$I9,1,0),0)) -> 0 | Z9: =IF($A9="","",IF($R9<0,"Negative",IF($Y9=1,"Below reorder","OK"))) -> OK | AA9: =IF($A9="","",IF(ISNUMBER($G9),$R9*$G9,"")) -> 7721.1 | AB9: =IF(COUNTA($A9:$M9)=0,"",IF($A9="","Missing: SKU",IF(COUNTIF($A$2:$A$101,$A9)>1,"Duplicate SKU",IF($B9="","Missing: product name",IF($C9="","Missing: category",IF($F9="","Missing: primary supplier",IF(NOT(ISNUMBER($H9)),"Missing: opening balance",IF(NOT(ISNUMBER($I9)),"Missing: reorder point",IF(NOT(ISNUMBER($J9)),"Missing: reorder qty",IF($L9="","Missing: status",IF(COUNTIF(Suppliers!$A$2:$A$51,$F9)=0,"Unknown supplier",IF(COUNTIF(Config!$N$15:$N$34,$C9)=0,"Unsupported category",IF(COUNTIF(Config!$O$15:$O$34,$L9)=0,"Unsupported status",IF($X9<>$H9,"Opening balance differs from lot openings",IF($W9<>$R9,"Lot balances differ from recorded stock",IF($R9<0,"Negative recorded stock","OK")))))))))))))))) -> OK | AC9: =IF($Y9=1,COUNTIF($Y$2:$Y9,1),"")
A10: CRE-UNF-500G | B10: Creatine Monohydrate, Unflavoured, 500 g | C10: Creatine | D10: Unflavoured | E10: 500 g | F10: SUP-04 | G10: 10.3 | H10: 640 | I10: 250 | J10: 700 | K10: 36 | L10: Active | N10: =IF($A10="","",IFERROR(INDEX(Suppliers!$B$2:$B$51,MATCH($F10,Suppliers!$A$2:$A$51,0))&"","(not found)")) -> Dunmore Powder Labs | O10: =IF($A10="","",SUMIFS(Inventory_Ledger!$E$2:$E$2001,Inventory_Ledger!$D$2:$D$2001,$A10,Inventory_Ledger!$C$2:$C$2001,"Receipt")) -> 0 | P10: =IF($A10="","",SUMIFS(Inventory_Ledger!$E$2:$E$2001,Inventory_Ledger!$D$2:$D$2001,$A10,Inventory_Ledger!$C$2:$C$2001,"Shipment")) -> 350 | Q10: =IF($A10="","",SUMIFS(Inventory_Ledger!$E$2:$E$2001,Inventory_Ledger!$D$2:$D$2001,$A10,Inventory_Ledger!$C$2:$C$2001,"Adjustment")) -> 0 | R10: =IF($A10="","",IF(ISNUMBER($H10),$H10,0)+$O10-$P10+$Q10) -> 290 | S10: =IF($A10="","",SUMIFS(Reservations!$L$2:$L$201,Reservations!$B$2:$B$201,$A10)) -> 80 | T10: =IF($A10="","",SUMIFS(Batches!$P$2:$P$301,Batches!$B$2:$B$301,$A10)) -> 0 | U10: =IF($A10="","",$R10-$S10-$T10) -> 210 | V10: =IF($A10="","",SUMIFS(Purchase_Orders!$N$2:$N$301,Purchase_Orders!$C$2:$C$301,$A10,Purchase_Orders!$O$2:$O$301,1)) -> 0 | W10: =IF($A10="","",SUMIFS(Batches!$L$2:$L$301,Batches!$B$2:$B$301,$A10)) -> 290 | X10: =IF($A10="","",SUMIFS(Batches!$F$2:$F$301,Batches!$B$2:$B$301,$A10)) -> 640 | Y10: =IF($A10="","",IF(ISNUMBER($I10),IF(IF(Config!$B$9="Recorded",$R10,$U10)<$I10,1,0),0)) -> 1 | Z10: =IF($A10="","",IF($R10<0,"Negative",IF($Y10=1,"Below reorder","OK"))) -> Below reorder | AA10: =IF($A10="","",IF(ISNUMBER($G10),$R10*$G10,"")) -> 2987 | AB10: =IF(COUNTA($A10:$M10)=0,"",IF($A10="","Missing: SKU",IF(COUNTIF($A$2:$A$101,$A10)>1,"Duplicate SKU",IF($B10="","Missing: product name",IF($C10="","Missing: category",IF($F10="","Missing: primary supplier",IF(NOT(ISNUMBER($H10)),"Missing: opening balance",IF(NOT(ISNUMBER($I10)),"Missing: reorder point",IF(NOT(ISNUMBER($J10)),"Missing: reorder qty",IF($L10="","Missing: status",IF(COUNTIF(Suppliers!$A$2:$A$51,$F10)=0,"Unknown supplier",IF(COUNTIF(Config!$N$15:$N$34,$C10)=0,"Unsupported category",IF(COUNTIF(Config!$O$15:$O$34,$L10)=0,"Unsupported status",IF($X10<>$H10,"Opening balance differs from lot openings",IF($W10<>$R10,"Lot balances differ from recorded stock",IF($R10<0,"Negative recorded stock","OK")))))))))))))))) -> OK | AC10: =IF($Y10=1,COUNTIF($Y$2:$Y10,1),"") -> 4
A11: PRE-BRZ-30 | B11: Pre-Workout, Blue Raspberry, 30 servings | C11: Pre-workout | D11: Blue raspberry | E11: 30 servings | F11: SUP-04 | G11: 9.6 | H11: 746 | I11: 300 | J11: 800 | K11: 24 | L11: Active | N11: =IF($A11="","",IFERROR(INDEX(Suppliers!$B$2:$B$51,MATCH($F11,Suppliers!$A$2:$A$51,0))&"","(not found)")) -> Dunmore Powder Labs | O11: =IF($A11="","",SUMIFS(Inventory_Ledger!$E$2:$E$2001,Inventory_Ledger!$D$2:$D$2001,$A11,Inventory_Ledger!$C$2:$C$2001,"Receipt")) -> 800 | P11: =IF($A11="","",SUMIFS(Inventory_Ledger!$E$2:$E$2001,Inventory_Ledger!$D$2:$D$2001,$A11,Inventory_Ledger!$C$2:$C$2001,"Shipment")) -> 671 | Q11: =IF($A11="","",SUMIFS(Inventory_Ledger!$E$2:$E$2001,Inventory_Ledger!$D$2:$D$2001,$A11,Inventory_Ledger!$C$2:$C$2001,"Adjustment")) -> 0 | R11: =IF($A11="","",IF(ISNUMBER($H11),$H11,0)+$O11-$P11+$Q11) -> 875 | S11: =IF($A11="","",SUMIFS(Reservations!$L$2:$L$201,Reservations!$B$2:$B$201,$A11)) -> 0 | T11: =IF($A11="","",SUMIFS(Batches!$P$2:$P$301,Batches!$B$2:$B$301,$A11)) -> 0 | U11: =IF($A11="","",$R11-$S11-$T11) -> 875 | V11: =IF($A11="","",SUMIFS(Purchase_Orders!$N$2:$N$301,Purchase_Orders!$C$2:$C$301,$A11,Purchase_Orders!$O$2:$O$301,1)) -> 0 | W11: =IF($A11="","",SUMIFS(Batches!$L$2:$L$301,Batches!$B$2:$B$301,$A11)) -> 875 | X11: =IF($A11="","",SUMIFS(Batches!$F$2:$F$301,Batches!$B$2:$B$301,$A11)) -> 746 | Y11: =IF($A11="","",IF(ISNUMBER($I11),IF(IF(Config!$B$9="Recorded",$R11,$U11)<$I11,1,0),0)) -> 0 | Z11: =IF($A11="","",IF($R11<0,"Negative",IF($Y11=1,"Below reorder","OK"))) -> OK | AA11: =IF($A11="","",IF(ISNUMBER($G11),$R11*$G11,"")) -> 8400 | AB11: =IF(COUNTA($A11:$M11)=0,"",IF($A11="","Missing: SKU",IF(COUNTIF($A$2:$A$101,$A11)>1,"Duplicate SKU",IF($B11="","Missing: product name",IF($C11="","Missing: category",IF($F11="","Missing: primary supplier",IF(NOT(ISNUMBER($H11)),"Missing: opening balance",IF(NOT(ISNUMBER($I11)),"Missing: reorder point",IF(NOT(ISNUMBER($J11)),"Missing: reorder qty",IF($L11="","Missing: status",IF(COUNTIF(Suppliers!$A$2:$A$51,$F11)=0,"Unknown supplier",IF(COUNTIF(Config!$N$15:$N$34,$C11)=0,"Unsupported category",IF(COUNTIF(Config!$O$15:$O$34,$L11)=0,"Unsupported status",IF($X11<>$H11,"Opening balance differs from lot openings",IF($W11<>$R11,"Lot balances differ from recorded stock",IF($R11<0,"Negative recorded stock","OK")))))))))))))))) -> OK | AC11: =IF($Y11=1,COUNTIF($Y$2:$Y11,1),"")
A12: PRE-WTM-30 | B12: Pre-Workout, Watermelon, 30 servings | C12: Pre-workout | D12: Watermelon | E12: 30 servings | F12: SUP-04 | G12: 9.6 | H12: 626 | I12: 200 | J12: 600 | K12: 24 | L12: Active | N12: =IF($A12="","",IFERROR(INDEX(Suppliers!$B$2:$B$51,MATCH($F12,Suppliers!$A$2:$A$51,0))&"","(not found)")) -> Dunmore Powder Labs | O12: =IF($A12="","",SUMIFS(Inventory_Ledger!$E$2:$E$2001,Inventory_Ledger!$D$2:$D$2001,$A12,Inventory_Ledger!$C$2:$C$2001,"Receipt")) -> 0 | P12: =IF($A12="","",SUMIFS(Inventory_Ledger!$E$2:$E$2001,Inventory_Ledger!$D$2:$D$2001,$A12,Inventory_Ledger!$C$2:$C$2001,"Shipment")) -> 374 | Q12: =IF($A12="","",SUMIFS(Inventory_Ledger!$E$2:$E$2001,Inventory_Ledger!$D$2:$D$2001,$A12,Inventory_Ledger!$C$2:$C$2001,"Adjustment")) -> -24 | R12: =IF($A12="","",IF(ISNUMBER($H12),$H12,0)+$O12-$P12+$Q12) -> 228 | S12: =IF($A12="","",SUMIFS(Reservations!$L$2:$L$201,Reservations!$B$2:$B$201,$A12)) -> 0 | T12: =IF($A12="","",SUMIFS(Batches!$P$2:$P$301,Batches!$B$2:$B$301,$A12)) -> 0 | U12: =IF($A12="","",$R12-$S12-$T12) -> 228 | V12: =IF($A12="","",SUMIFS(Purchase_Orders!$N$2:$N$301,Purchase_Orders!$C$2:$C$301,$A12,Purchase_Orders!$O$2:$O$301,1)) -> 600 | W12: =IF($A12="","",SUMIFS(Batches!$L$2:$L$301,Batches!$B$2:$B$301,$A12)) -> 228 | X12: =IF($A12="","",SUMIFS(Batches!$F$2:$F$301,Batches!$B$2:$B$301,$A12)) -> 626 | Y12: =IF($A12="","",IF(ISNUMBER($I12),IF(IF(Config!$B$9="Recorded",$R12,$U12)<$I12,1,0),0)) -> 0 | Z12: =IF($A12="","",IF($R12<0,"Negative",IF($Y12=1,"Below reorder","OK"))) -> OK | AA12: =IF($A12="","",IF(ISNUMBER($G12),$R12*$G12,"")) -> 2188.8 | AB12: =IF(COUNTA($A12:$M12)=0,"",IF($A12="","Missing: SKU",IF(COUNTIF($A$2:$A$101,$A12)>1,"Duplicate SKU",IF($B12="","Missing: product name",IF($C12="","Missing: category",IF($F12="","Missing: primary supplier",IF(NOT(ISNUMBER($H12)),"Missing: opening balance",IF(NOT(ISNUMBER($I12)),"Missing: reorder point",IF(NOT(ISNUMBER($J12)),"Missing: reorder qty",IF($L12="","Missing: status",IF(COUNTIF(Suppliers!$A$2:$A$51,$F12)=0,"Unknown supplier",IF(COUNTIF(Config!$N$15:$N$34,$C12)=0,"Unsupported category",IF(COUNTIF(Config!$O$15:$O$34,$L12)=0,"Unsupported status",IF($X12<>$H12,"Opening balance differs from lot openings",IF($W12<>$R12,"Lot balances differ from recorded stock",IF($R12<0,"Negative recorded stock","OK")))))))))))))))) -> OK | AC12: =IF($Y12=1,COUNTIF($Y$2:$Y12,1),"")
